KeyError: 'chrom'
(seq_env) jiangd@NE060250W79682D:/mnt/e/Data/seq_for_human_293t2/barcode04$ python3 TSS_5hmc_5mc.py
Extracting TSS from GTF...
Found 62700 genes

Found 4 samples

Processing barcode04...
Filtering TSS regions:   0%|                                                                                                                                                           | 0/62700 [00:00<?, ?it/s]
Traceback (most recent call last):
  File "/mnt/e/venvs/seq_env/lib/python3.12/site-packages/pandas/core/indexes/base.py", line 3812, in get_loc
    return self._engine.get_loc(casted_key)
           ^^^^^^^^^^^^^^^^^^^^^^^^^^^^^^^^
  File "pandas/_libs/index.pyx", line 167, in pandas._libs.index.IndexEngine.get_loc
  File "pandas/_libs/index.pyx", line 196, in pandas._libs.index.IndexEngine.get_loc
  File "pandas/_libs/hashtable_class_helper.pxi", line 7088, in pandas._libs.hashtable.PyObjectHashTable.get_item
  File "pandas/_libs/hashtable_class_helper.pxi", line 7096, in pandas._libs.hashtable.PyObjectHashTable.get_item
KeyError: '#chrom'

The above exception was the direct cause of the following exception:

Traceback (most recent call last):
  File "/mnt/e/Data/seq_for_human_293t2/barcode04/TSS_5hmc_5mc.py", line 79, in <module>
    (meth_df['#chrom'] == tss_row['#chrom']) &
     ~~~~~~~^^^^^^^^^^
  File "/mnt/e/venvs/seq_env/lib/python3.12/site-packages/pandas/core/frame.py", line 4113, in __getitem__
    indexer = self.columns.get_loc(key)
              ^^^^^^^^^^^^^^^^^^^^^^^^^
  File "/mnt/e/venvs/seq_env/lib/python3.12/site-packages/pandas/core/indexes/base.py", line 3819, in get_loc
    raise KeyError(key) from err
KeyError: '#chrom'
(seq_env) jiangd@NE060250W79682D:/mnt/e/Data/seq_for_human_293t2/barcode04$
